Workbook
Name \c: 'Work Report Consultant'!#REF!
Name \c: 'Work Report Consultant'!#REF!
Name \c: 'Work Report Consultant'!#REF!
Name \c: 'Work Report Consultant'!#REF!
Name \c: 'Work Report Consultant'!#REF!
Name \c: 'Work Report Consultant'!#REF!
Name \c: 'Work Report Consultant'!#REF!
Name \c: 'Work Report Consultant'!#REF!
Name \c: 'Work Report Consultant'!#REF!
Name \c: 'Work Report Consultant'!#REF!
Name \c: 'Work Report Consultant'!#REF!
Name \c: 'Work Report Consultant'!#REF!
Name \d: 'Work Report Consultant'!#REF!
Name \d: 'Work Report Consultant'!#REF!
Name \d: 'Work Report Consultant'!#REF!
Name \d: 'Work Report Consultant'!#REF!
Name \d: 'Work Report Consultant'!#REF!
Name \d: 'Work Report Consultant'!#REF!
Name \d: 'Work Report Consultant'!#REF!
Name \d: 'Work Report Consultant'!#REF!
Name \d: 'Work Report Consultant'!#REF!
Name \d: 'Work Report Consultant'!#REF!
Name \d: 'Work Report Consultant'!#REF!
Name \d: 'Work Report Consultant'!#REF!
Name \s: 'Work Report Consultant'!$BR$7
Name \t: 'Work Report Consultant'!$BR$10
Name \y: 'Work Report Consultant'!#REF!
Name \y: 'Work Report Consultant'!#REF!
Name \y: 'Work Report Consultant'!#REF!
Name \y: 'Work Report Consultant'!#REF!
Name \y: 'Work Report Consultant'!#REF!
Name \y: 'Work Report Consultant'!#REF!
Name \y: 'Work Report Consultant'!#REF!
Name \y: 'Work Report Consultant'!#REF!
Name \y: 'Work Report Consultant'!#REF!
Name \y: 'Work Report Consultant'!#REF!
Name \y: 'Work Report Consultant'!#REF!
Name \y: 'Work Report Consultant'!#REF!
Name Druckbereich_MI: 'Work Report Consultant'!$B$2:$Y$75
Name DRUCKBEREICH_MI: 'Work Report Consultant'!$B$2:$Y$75
Name MAKRO: 'Work Report Consultant'!$BQ$4
Name SASO: 'Work Report Consultant'!$BT$7:$BV$8
Name TEMP: 'Work Report Consultant'!$D$10
Name WOCHE: 'Work Report Consultant'!$B$8:$B$14

Sheet Work Report Consultant
B2: Consultant work report 2026 | P2: ANAVIA AG
B3: Name: | E3: Jorge Benito Sanabrias | M3: Dept: | R3: Anzen Engineering Switzerland | AV3: 2026
B4: JANUARY | F4: FEBRUARY | J4: MARCH | N4: APRIL | R4: MAY | V4: JUNE | AA4: January | AB4: February | AC4: March | AD4: April | AE4: May | AF4: June
B5: =WEEKDAY(5,1) -> 5 | C5: 1 | D5: Neujahr | E5: 1 | F5: =B35+1 -> 36 | G5: 1 | H5: N/A | I5: =E35+1 -> 32 | J5: =F32+1 -> 64 | K5: 1 | L5: N/A | M5: =I32+1 -> 60 | N5: =J35+1 -> 95 | O5: 1 | P5: Day | Q5: =M35+1 -> 91 | R5: =N34+1 -> 125 | S5: 1 | T5: Day | U5: =Q34+1 -> 121 | V5: =R35+1 -> 156 | W5: 1 | X5: Holiday | Y5: =U35+1 -> 152 | AA5: =IF(D5="Day",1,IF(D5="1/2 Day",0.5,IF(D5="Day Special",1.2,"NA"))) -> NA | AB5: =IF(H5="Day",1,IF(H5="1/2 Day",0.5,IF(H5="Day Special",1.2,"NA"))) -> NA | AC5: =IF(L5="Day",1,IF(L5="1/2 Day",0.5,IF(L5="Day Special",1.2,"NA"))) -> NA | AD5: =IF(P5="Day",1,IF(P5="1/2 Day",0.5,IF(P5="Day Special",1.2,"NA"))) -> 1 | AE5: =IF(T5="Day",1,IF(T5="1/2 Day",0.5,IF(D5="Day Special",1.2,"NA"))) -> 1 | AF5: =IF(X5="Day",1,IF(X5="1/2 Day",0.5,IF(X5="Day Special",1.2,"NA"))) -> NA
B6: =B5+1 -> 6 | C6: 2 | D6: N/A | E6: =E5+1 -> 2 | F6: =F5+1 -> 37 | G6: 2 | H6: N/A | I6: =I5+1 -> 33 | J6: =J5+1 -> 65 | K6: 2 | L6: N/A | M6: =M5+1 -> 61 | N6: =N5+1 -> 96 | O6: =O5+1 -> 2 | P6: Day | Q6: =Q5+1 -> 92 | R6: =R5+1 -> 126 | S6: =S5+1 -> 2 | T6: N/A | U6: =U5+1 -> 122 | V6: =V5+1 -> 157 | W6: =W5+1 -> 2 | X6: Holiday | Y6: =Y5+1 -> 153 | AA6: =IF(D6="Day",1,IF(D6="1/2 Day",0.5,IF(D6="Day Special",1.2,"NA"))) -> NA | AB6: =IF(H6="Day",1,IF(H6="1/2 Day",0.5,IF(H6="Day Special",1.2,"NA"))) -> NA | AC6: =IF(L6="Day",1,IF(L6="1/2 Day",0.5,IF(L6="Day Special",1.2,"NA"))) -> NA | AD6: =IF(P6="Day",1,IF(P6="1/2 Day",0.5,IF(P6="Day Special",1.2,"NA"))) -> 1 | AE6: =IF(T6="Day",1,IF(T6="1/2 Day",0.5,IF(D6="Day Special",1.2,"NA"))) -> NA | AF6: =IF(X6="Day",1,IF(X6="1/2 Day",0.5,IF(X6="Day Special",1.2,"NA"))) -> NA
B7: =B6+1 -> 7 | C7: 3 | D7: N/A | E7: =E6+1 -> 3 | F7: =F6+1 -> 38 | G7: 4 | H7: N/A | I7: =I6+1 -> 34 | J7: =J6+1 -> 66 | K7: 3 | L7: N/A | M7: =M6+1 -> 62 | N7: =N6+1 -> 97 | O7: =O6+1 -> 3 | P7: Karfreitag | Q7: =Q6+1 -> 93 | R7: =R6+1 -> 127 | S7: =S6+1 -> 3 | T7: N/A | U7: =U6+1 -> 123 | V7: =V6+1 -> 158 | W7: =W6+1 -> 3 | X7: Holiday | Y7: =Y6+1 -> 154 | AA7: =IF(D7="Day",1,IF(D7="1/2 Day",0.5,IF(D7="Day Special",1.2,"NA"))) -> NA | AB7: =IF(H7="Day",1,IF(H7="1/2 Day",0.5,IF(H7="Day Special",1.2,"NA"))) -> NA | AC7: =IF(L7="Day",1,IF(L7="1/2 Day",0.5,IF(L7="Day Special",1.2,"NA"))) -> NA | AD7: =IF(P7="Day",1,IF(P7="1/2 Day",0.5,IF(P7="Day Special",1.2,"NA"))) -> NA | AE7: =IF(T7="Day",1,IF(T7="1/2 Day",0.5,IF(D7="Day Special",1.2,"NA"))) -> NA | AF7: =IF(X7="Day",1,IF(X7="1/2 Day",0.5,IF(X7="Day Special",1.2,"NA"))) -> NA | AV7: Day
B8: =B7+1 -> 8 | C8: 4 | D8: N/A | E8: =E7+1 -> 4 | F8: =F7+1 -> 39 | G8: 4 | H8: N/A | I8: =I7+1 -> 35 | J8: =J7+1 -> 67 | K8: 4 | L8: N/A | M8: =M7+1 -> 63 | N8: =N7+1 -> 98 | O8: =O7+1 -> 4 | P8: N/A | Q8: =Q7+1 -> 94 | R8: =R7+1 -> 128 | S8: =S7+1 -> 4 | T8: Day | U8: =U7+1 -> 124 | V8: =V7+1 -> 159 | W8: =W7+1 -> 4 | X8: Holiday | Y8: =Y7+1 -> 155 | AA8: =IF(D8="Day",1,IF(D8="1/2 Day",0.5,IF(D8="Day Special",1.2,"NA"))) -> NA | AB8: =IF(H8="Day",1,IF(H8="1/2 Day",0.5,IF(H8="Day Special",1.2,"NA"))) -> NA | AC8: =IF(L8="Day",1,IF(L8="1/2 Day",0.5,IF(L8="Day Special",1.2,"NA"))) -> NA | AD8: =IF(P8="Day",1,IF(P8="1/2 Day",0.5,IF(P8="Day Special",1.2,"NA"))) -> NA | AE8: =IF(T8="Day",1,IF(T8="1/2 Day",0.5,IF(D8="Day Special",1.2,"NA"))) -> 1 | AF8: =IF(X8="Day",1,IF(X8="1/2 Day",0.5,IF(X8="Day Special",1.2,"NA"))) -> NA | AV8: 1/2 Day
B9: =B8+1 -> 9 | C9: 5 | D9: N/A | E9: =E8+1 -> 5 | F9: =F8+1 -> 40 | G9: 5 | H9: N/A | I9: =I8+1 -> 36 | J9: =J8+1 -> 68 | K9: 5 | L9: N/A | M9: =M8+1 -> 64 | N9: =N8+1 -> 99 | O9: =O8+1 -> 5 | P9: Ostern | Q9: =Q8+1 -> 95 | R9: =R8+1 -> 129 | S9: =S8+1 -> 5 | T9: Day | U9: =U8+1 -> 125 | V9: =V8+1 -> 160 | W9: =W8+1 -> 5 | X9: Holiday | Y9: =Y8+1 -> 156 | AA9: =IF(D9="Day",1,IF(D9="1/2 Day",0.5,IF(D9="Day Special",1.2,"NA"))) -> NA | AB9: =IF(H9="Day",1,IF(H9="1/2 Day",0.5,IF(H9="Day Special",1.2,"NA"))) -> NA | AC9: =IF(L9="Day",1,IF(L9="1/2 Day",0.5,IF(L9="Day Special",1.2,"NA"))) -> NA | AD9: =IF(P9="Day",1,IF(P9="1/2 Day",0.5,IF(P9="Day Special",1.2,"NA"))) -> NA | AE9: =IF(T9="Day",1,IF(T9="1/2 Day",0.5,IF(D9="Day Special",1.2,"NA"))) -> 1 | AF9: =IF(X9="Day",1,IF(X9="1/2 Day",0.5,IF(X9="Day Special",1.2,"NA"))) -> NA | AV9: Holiday
B10: =B9+1 -> 10 | C10: 6 | D10: N/A | E10: =E9+1 -> 6 | F10: =F9+1 -> 41 | G10: 6 | H10: N/A | I10: =I9+1 -> 37 | J10: =J9+1 -> 69 | K10: 6 | L10: N/A | M10: =M9+1 -> 65 | N10: =N9+1 -> 100 | O10: =O9+1 -> 6 | P10: Ostermontag | Q10: =Q9+1 -> 96 | R10: =R9+1 -> 130 | S10: =S9+1 -> 6 | T10: Day | U10: =U9+1 -> 126 | V10: =V9+1 -> 161 | W10: =W9+1 -> 6 | X10: N/A | Y10: =Y9+1 -> 157 | AA10: =IF(D10="Day",1,IF(D10="1/2 Day",0.5,IF(D10="Day Special",1.2,"NA"))) -> NA | AB10: =IF(H10="Day",1,IF(H10="1/2 Day",0.5,IF(H10="Day Special",1.2,"NA"))) -> NA | AC10: =IF(L10="Day",1,IF(L10="1/2 Day",0.5,IF(L10="Day Special",1.2,"NA"))) -> NA | AD10: =IF(P10="Day",1,IF(P10="1/2 Day",0.5,IF(P10="Day Special",1.2,"NA"))) -> NA | AE10: =IF(T10="Day",1,IF(T10="1/2 Day",0.5,IF(D10="Day Special",1.2,"NA"))) -> 1 | AF10: =IF(X10="Day",1,IF(X10="1/2 Day",0.5,IF(X10="Day Special",1.2,"NA"))) -> NA | AV10: Business Trip
B11: =B10+1 -> 11 | C11: 7 | D11: N/A | E11: =E10+1 -> 7 | F11: =F10+1 -> 42 | G11: 7 | H11: N/A | I11: =I10+1 -> 38 | J11: =J10+1 -> 70 | K11: 7 | L11: N/A | M11: =M10+1 -> 66 | N11: =N10+1 -> 101 | O11: =O10+1 -> 7 | P11: Day | Q11: =Q10+1 -> 97 | R11: =R10+1 -> 131 | S11: =S10+1 -> 7 | T11: Day | U11: =U10+1 -> 127 | V11: =V10+1 -> 162 | W11: =W10+1 -> 7 | X11: N/A | Y11: =Y10+1 -> 158 | AA11: =IF(D11="Day",1,IF(D11="1/2 Day",0.5,IF(D11="Day Special",1.2,"NA"))) -> NA | AB11: =IF(H11="Day",1,IF(H11="1/2 Day",0.5,IF(H11="Day Special",1.2,"NA"))) -> NA | AC11: =IF(L11="Day",1,IF(L11="1/2 Day",0.5,IF(L11="Day Special",1.2,"NA"))) -> NA | AD11: =IF(P11="Day",1,IF(P11="1/2 Day",0.5,IF(P11="Day Special",1.2,"NA"))) -> 1 | AE11: =IF(T11="Day",1,IF(T11="1/2 Day",0.5,IF(D11="Day Special",1.2,"NA"))) -> 1 | AF11: =IF(X11="Day",1,IF(X11="1/2 Day",0.5,IF(X11="Day Special",1.2,"NA"))) -> NA | AV11: N/A
B12: =B11+1 -> 12 | C12: 8 | D12: N/A | E12: =E11+1 -> 8 | F12: =F11+1 -> 43 | G12: 8 | H12: N/A | I12: =I11+1 -> 39 | J12: =J11+1 -> 71 | K12: 8 | L12: N/A | M12: =M11+1 -> 67 | N12: =N11+1 -> 102 | O12: =O11+1 -> 8 | P12: Day | Q12: =Q11+1 -> 98 | R12: =R11+1 -> 132 | S12: =S11+1 -> 8 | T12: Day | U12: =U11+1 -> 128 | V12: =V11+1 -> 163 | W12: =W11+1 -> 8 | X12: Holiday | Y12: =Y11+1 -> 159 | AA12: =IF(D12="Day",1,IF(D12="1/2 Day",0.5,IF(D12="Day Special",1.2,"NA"))) -> NA | AB12: =IF(H12="Day",1,IF(H12="1/2 Day",0.5,IF(H12="Day Special",1.2,"NA"))) -> NA | AC12: =IF(L12="Day",1,IF(L12="1/2 Day",0.5,IF(L12="Day Special",1.2,"NA"))) -> NA | AD12: =IF(P12="Day",1,IF(P12="1/2 Day",0.5,IF(P12="Day Special",1.2,"NA"))) -> 1 | AE12: =IF(T12="Day",1,IF(T12="1/2 Day",0.5,IF(D12="Day Special",1.2,"NA"))) -> 1 | AF12: =IF(X12="Day",1,IF(X12="1/2 Day",0.5,IF(X12="Day Special",1.2,"NA"))) -> NA | AV12: Neujahr
B13: =B12+1 -> 13 | C13: 9 | D13: N/A | E13: =E12+1 -> 9 | F13: =F12+1 -> 44 | G13: 9 | H13: N/A | I13: =I12+1 -> 40 | J13: =J12+1 -> 72 | K13: 9 | L13: N/A | M13: =M12+1 -> 68 | N13: =N12+1 -> 103 | O13: =O12+1 -> 9 | P13: Day | Q13: =Q12+1 -> 99 | R13: =R12+1 -> 133 | S13: =S12+1 -> 9 | T13: N/A | U13: =U12+1 -> 129 | V13: =V12+1 -> 164 | W13: =W12+1 -> 9 | X13: Day | Y13: =Y12+1 -> 160 | AA13: =IF(D13="Day",1,IF(D13="1/2 Day",0.5,IF(D13="Day Special",1.2,"NA"))) -> NA | AB13: =IF(H13="Day",1,IF(H13="1/2 Day",0.5,IF(H13="Day Special",1.2,"NA"))) -> NA | AC13: =IF(L13="Day",1,IF(L13="1/2 Day",0.5,IF(L13="Day Special",1.2,"NA"))) -> NA | AD13: =IF(P13="Day",1,IF(P13="1/2 Day",0.5,IF(P13="Day Special",1.2,"NA"))) -> 1 | AE13: =IF(T13="Day",1,IF(T13="1/2 Day",0.5,IF(D13="Day Special",1.2,"NA"))) -> NA | AF13: =IF(X13="Day",1,IF(X13="1/2 Day",0.5,IF(X13="Day Special",1.2,"NA"))) -> 1 | AV13: K (Day)
B14: =B13+1 -> 14 | C14: 10 | D14: N/A | E14: =E13+1 -> 10 | F14: =F13+1 -> 45 | G14: 10 | H14: N/A | I14: =I13+1 -> 41 | J14: =J13+1 -> 73 | K14: 10 | L14: Day | M14: =M13+1 -> 69 | N14: =N13+1 -> 104 | O14: =O13+1 -> 10 | P14: Day | Q14: =Q13+1 -> 100 | R14: =R13+1 -> 134 | S14: =S13+1 -> 10 | T14: N/A | U14: =U13+1 -> 130 | V14: =V13+1 -> 165 | W14: =W13+1 -> 10 | X14: Day | Y14: =Y13+1 -> 161 | AA14: =IF(D14="Day",1,IF(D14="1/2 Day",0.5,IF(D14="Day Special",1.2,"NA"))) -> NA | AB14: =IF(H14="Day",1,IF(H14="1/2 Day",0.5,IF(H14="Day Special",1.2,"NA"))) -> NA | AC14: =IF(L14="Day",1,IF(L14="1/2 Day",0.5,IF(L14="Day Special",1.2,"NA"))) -> 1 | AD14: =IF(P14="Day",1,IF(P14="1/2 Day",0.5,IF(P14="Day Special",1.2,"NA"))) -> 1 | AE14: =IF(T14="Day",1,IF(T14="1/2 Day",0.5,IF(D14="Day Special",1.2,"NA"))) -> NA | AF14: =IF(X14="Day",1,IF(X14="1/2 Day",0.5,IF(X14="Day Special",1.2,"NA"))) -> 1 | AV14: Josefstag
B15: =B14+1 -> 15 | C15: 11 | D15: N/A | E15: =E14+1 -> 11 | F15: =F14+1 -> 46 | G15: 11 | H15: N/A | I15: =I14+1 -> 42 | J15: =J14+1 -> 74 | K15: 11 | L15: Day | M15: =M14+1 -> 70 | N15: =N14+1 -> 105 | O15: =O14+1 -> 11 | P15: N/A | Q15: =Q14+1 -> 101 | R15: =R14+1 -> 135 | S15: =S14+1 -> 11 | T15: Day | U15: =U14+1 -> 131 | V15: =V14+1 -> 166 | W15: =W14+1 -> 11 | X15: Day | Y15: =Y14+1 -> 162 | AA15: =IF(D15="Day",1,IF(D15="1/2 Day",0.5,IF(D15="Day Special",1.2,"NA"))) -> NA | AB15: =IF(H15="Day",1,IF(H15="1/2 Day",0.5,IF(H15="Day Special",1.2,"NA"))) -> NA | AC15: =IF(L15="Day",1,IF(L15="1/2 Day",0.5,IF(L15="Day Special",1.2,"NA"))) -> 1 | AD15: =IF(P15="Day",1,IF(P15="1/2 Day",0.5,IF(P15="Day Special",1.2,"NA"))) -> NA | AE15: =IF(T15="Day",1,IF(T15="1/2 Day",0.5,IF(D15="Day Special",1.2,"NA"))) -> 1 | AF15: =IF(X15="Day",1,IF(X15="1/2 Day",0.5,IF(X15="Day Special",1.2,"NA"))) -> 1 | AV15: Karfreitag
B16: =B15+1 -> 16 | C16: 12 | D16: N/A | E16: =E15+1 -> 12 | F16: =F15+1 -> 47 | G16: 12 | H16: N/A | I16: =I15+1 -> 43 | J16: =J15+1 -> 75 | K16: 12 | L16: Day | M16: =M15+1 -> 71 | N16: =N15+1 -> 106 | O16: =O15+1 -> 12 | P16: N/A | Q16: =Q15+1 -> 102 | R16: =R15+1 -> 136 | S16: =S15+1 -> 12 | T16: Day | U16: =U15+1 -> 132 | V16: =V15+1 -> 167 | W16: =W15+1 -> 12 | X16: Day | Y16: =Y15+1 -> 163 | AA16: =IF(D16="Day",1,IF(D16="1/2 Day",0.5,IF(D16="Day Special",1.2,"NA"))) -> NA | AB16: =IF(H16="Day",1,IF(H16="1/2 Day",0.5,IF(H16="Day Special",1.2,"NA"))) -> NA | AC16: =IF(L16="Day",1,IF(L16="1/2 Day",0.5,IF(L16="Day Special",1.2,"NA"))) -> 1 | AD16: =IF(P16="Day",1,IF(P16="1/2 Day",0.5,IF(P16="Day Special",1.2,"NA"))) -> NA | AE16: =IF(T16="Day",1,IF(T16="1/2 Day",0.5,IF(D16="Day Special",1.2,"NA"))) -> 1 | AF16: =IF(X16="Day",1,IF(X16="1/2 Day",0.5,IF(X16="Day Special",1.2,"NA"))) -> 1 | AV16: Ostern
B17: =B16+1 -> 17 | C17: 13 | D17: N/A | E17: =E16+1 -> 13 | F17: =F16+1 -> 48 | G17: 13 | H17: N/A | I17: =I16+1 -> 44 | J17: =J16+1 -> 76 | K17: 13 | L17: Day | M17: =M16+1 -> 72 | N17: =N16+1 -> 107 | O17: =O16+1 -> 13 | P17: Day | Q17: =Q16+1 -> 103 | R17: =R16+1 -> 137 | S17: =S16+1 -> 13 | T17: Day | U17: =U16+1 -> 133 | V17: =V16+1 -> 168 | W17: =W16+1 -> 13 | X17: N/A | Y17: =Y16+1 -> 164 | AA17: =IF(D17="Day",1,IF(D17="1/2 Day",0.5,IF(D17="Day Special",1.2,"NA"))) -> NA | AB17: =IF(H17="Day",1,IF(H17="1/2 Day",0.5,IF(H17="Day Special",1.2,"NA"))) -> NA | AC17: =IF(L17="Day",1,IF(L17="1/2 Day",0.5,IF(L17="Day Special",1.2,"NA"))) -> 1 | AD17: =IF(P17="Day",1,IF(P17="1/2 Day",0.5,IF(P17="Day Special",1.2,"NA"))) -> 1 | AE17: =IF(T17="Day",1,IF(T17="1/2 Day",0.5,IF(D17="Day Special",1.2,"NA"))) -> 1 | AF17: =IF(X17="Day",1,IF(X17="1/2 Day",0.5,IF(X17="Day Special",1.2,"NA"))) -> NA | AV17: Ostermontag
B18: =B17+1 -> 18 | C18: 14 | D18: N/A | E18: =E17+1 -> 14 | F18: =F17+1 -> 49 | G18: 14 | H18: N/A | I18: =I17+1 -> 45 | J18: =J17+1 -> 77 | K18: 14 | L18: N/A | M18: =M17+1 -> 73 | N18: =N17+1 -> 108 | O18: =O17+1 -> 14 | P18: Day | Q18: =Q17+1 -> 104 | R18: =R17+1 -> 138 | S18: =S17+1 -> 14 | T18: Himmelfahrt | U18: =U17+1 -> 134 | V18: =V17+1 -> 169 | W18: =W17+1 -> 14 | X18: N/A | Y18: =Y17+1 -> 165 | AA18: =IF(D18="Day",1,IF(D18="1/2 Day",0.5,IF(D18="Day Special",1.2,"NA"))) -> NA | AB18: =IF(H18="Day",1,IF(H18="1/2 Day",0.5,IF(H18="Day Special",1.2,"NA"))) -> NA | AC18: =IF(L18="Day",1,IF(L18="1/2 Day",0.5,IF(L18="Day Special",1.2,"NA"))) -> NA | AD18: =IF(P18="Day",1,IF(P18="1/2 Day",0.5,IF(P18="Day Special",1.2,"NA"))) -> 1 | AE18: =IF(T18="Day",1,IF(T18="1/2 Day",0.5,IF(D18="Day Special",1.2,"NA"))) -> NA | AF18: =IF(X18="Day",1,IF(X18="1/2 Day",0.5,IF(X18="Day Special",1.2,"NA"))) -> NA | AV18: Auffahrt
... B27: =B26+1 -> 27 | C27: 23 | D27: N/A | E27: =E26+1 -> 23 | F27: =F26+1 -> 58 | G27: 23 | H27: N/A | I27: =I26+1 -> 54 | J27: =J26+1 -> 86 | K27: 23 | L27: Day | M27: =M26+1 -> 82 | N27: =N26+1 -> 117 | O27: =O26+1 -> 23 | P27: Day | Q27: =Q26+1 -> 113 | R27: =R26+1 -> 147 | S27: =S26+1 -> 23 | T27: N/A | U27: =U26+1 -> 143 | V27: =V26+1 -> 178 | W27: =W26+1 -> 23 | X27: Day | Y27: =Y26+1 -> 174 | AA27: =IF(D27="Day",1,IF(D27="1/2 Day",0.5,IF(D27="Day Special",1.2,"NA"))) -> NA | AB27: =IF(H27="Day",1,IF(H27="1/2 Day",0.5,IF(H27="Day Special",1.2,"NA"))) -> NA | AC27: =IF(L27="Day",1,IF(L27="1/2 Day",0.5,IF(L27="Day Special",1.2,"NA"))) -> 1 | AD27: =IF(P27="Day",1,IF(P27="1/2 Day",0.5,IF(P27="Day Special",1.2,"NA"))) -> 1 | AE27: =IF(T27="Day",1,IF(T27="1/2 Day",0.5,IF(D27="Day Special",1.2,"NA"))) -> NA | AF27: =IF(X27="Day",1,IF(X27="1/2 Day",0.5,IF(X27="Day Special",1.2,"NA"))) -> 1 | AV27: Company Closed
B28: =B27+1 -> 28 | C28: 24 | D28: N/A | E28: =E27+1 -> 24 | F28: =F27+1 -> 59 | G28: 24 | H28: N/A | I28: =I27+1 -> 55 | J28: =J27+1 -> 87 | K28: 24 | L28: Day | M28: =M27+1 -> 83 | N28: =N27+1 -> 118 | O28: =O27+1 -> 24 | P28: Day | Q28: =Q27+1 -> 114 | R28: =R27+1 -> 148 | S28: =S27+1 -> 24 | T28: N/A | U28: =U27+1 -> 144 | V28: =V27+1 -> 179 | W28: =W27+1 -> 24 | X28: Day | Y28: =Y27+1 -> 175 | AA28: =IF(D28="Day",1,IF(D28="1/2 Day",0.5,IF(D28="Day Special",1.2,"NA"))) -> NA | AB28: =IF(H28="Day",1,IF(H28="1/2 Day",0.5,IF(H28="Day Special",1.2,"NA"))) -> NA | AC28: =IF(L28="Day",1,IF(L28="1/2 Day",0.5,IF(L28="Day Special",1.2,"NA"))) -> 1 | AD28: =IF(P28="Day",1,IF(P28="1/2 Day",0.5,IF(P28="Day Special",1.2,"NA"))) -> 1 | AE28: =IF(T28="Day",1,IF(T28="1/2 Day",0.5,IF(D28="Day Special",1.2,"NA"))) -> NA | AF28: =IF(X28="Day",1,IF(X28="1/2 Day",0.5,IF(X28="Day Special",1.2,"NA"))) -> 1
B29: =B28+1 -> 29 | C29: 25 | D29: N/A | E29: =E28+1 -> 25 | F29: =F28+1 -> 60 | G29: 25 | H29: N/A | I29: =I28+1 -> 56 | J29: =J28+1 -> 88 | K29: 25 | L29: Day | M29: =M28+1 -> 84 | N29: =N28+1 -> 119 | O29: =O28+1 -> 25 | P29: N/A | Q29: =Q28+1 -> 115 | R29: =R28+1 -> 149 | S29: =S28+1 -> 25 | T29: Pfingstmontag | U29: =U28+1 -> 145 | V29: =V28+1 -> 180 | W29: =W28+1 -> 25 | X29: Day | Y29: =Y28+1 -> 176 | AA29: =IF(D29="Day",1,IF(D29="1/2 Day",0.5,IF(D29="Day Special",1.2,"NA"))) -> NA | AB29: =IF(H29="Day",1,IF(H29="1/2 Day",0.5,IF(H29="Day Special",1.2,"NA"))) -> NA | AC29: =IF(L29="Day",1,IF(L29="1/2 Day",0.5,IF(L29="Day Special",1.2,"NA"))) -> 1 | AD29: =IF(P29="Day",1,IF(P29="1/2 Day",0.5,IF(P29="Day Special",1.2,"NA"))) -> NA | AE29: =IF(T29="Day",1,IF(T29="1/2 Day",0.5,IF(D29="Day Special",1.2,"NA"))) -> NA | AF29: =IF(X29="Day",1,IF(X29="1/2 Day",0.5,IF(X29="Day Special",1.2,"NA"))) -> 1 | AV29: - Select from List -
B30: =B29+1 -> 30 | C30: 26 | D30: N/A | E30: =E29+1 -> 26 | F30: =F29+1 -> 61 | G30: 26 | H30: N/A | I30: =I29+1 -> 57 | J30: =J29+1 -> 89 | K30: 26 | L30: Day | M30: =M29+1 -> 85 | N30: =N29+1 -> 120 | O30: =O29+1 -> 26 | P30: N/A | Q30: =Q29+1 -> 116 | R30: =R29+1 -> 150 | S30: =S29+1 -> 26 | T30: N/A | U30: =U29+1 -> 146 | V30: =V29+1 -> 181 | W30: =W29+1 -> 26 | X30: Day | Y30: =Y29+1 -> 177 | AA30: =IF(D30="Day",1,IF(D30="1/2 Day",0.5,IF(D30="Day Special",1.2,"NA"))) -> NA | AB30: =IF(H30="Day",1,IF(H30="1/2 Day",0.5,IF(H30="Day Special",1.2,"NA"))) -> NA | AC30: =IF(L30="Day",1,IF(L30="1/2 Day",0.5,IF(L30="Day Special",1.2,"NA"))) -> 1 | AD30: =IF(P30="Day",1,IF(P30="1/2 Day",0.5,IF(P30="Day Special",1.2,"NA"))) -> NA | AE30: =IF(T30="Day",1,IF(T30="1/2 Day",0.5,IF(D30="Day Special",1.2,"NA"))) -> NA | AF30: =IF(X30="Day",1,IF(X30="1/2 Day",0.5,IF(X30="Day Special",1.2,"NA"))) -> 1 | AV30: TCS
B31: =B30+1 -> 31 | C31: 27 | D31: N/A | E31: =E30+1 -> 27 | F31: =F30+1 -> 62 | G31: 27 | H31: N/A | I31: =I30+1 -> 58 | J31: =J30+1 -> 90 | K31: 27 | L31: Day | M31: =M30+1 -> 86 | N31: =N30+1 -> 121 | O31: =O30+1 -> 27 | P31: Day | Q31: =Q30+1 -> 117 | R31: =R30+1 -> 151 | S31: =S30+1 -> 27 | T31: N/A | U31: =U30+1 -> 147 | V31: =V30+1 -> 182 | W31: =W30+1 -> 27 | X31: N/A | Y31: =Y30+1 -> 178 | AA31: =IF(D31="Day",1,IF(D31="1/2 Day",0.5,IF(D31="Day Special",1.2,"NA"))) -> NA | AB31: =IF(H31="Day",1,IF(H31="1/2 Day",0.5,IF(H31="Day Special",1.2,"NA"))) -> NA | AC31: =IF(L31="Day",1,IF(L31="1/2 Day",0.5,IF(L31="Day Special",1.2,"NA"))) -> 1 | AD31: =IF(P31="Day",1,IF(P31="1/2 Day",0.5,IF(P31="Day Special",1.2,"NA"))) -> 1 | AE31: =IF(T31="Day",1,IF(T31="1/2 Day",0.5,IF(D31="Day Special",1.2,"NA"))) -> NA | AF31: =IF(X31="Day",1,IF(X31="1/2 Day",0.5,IF(X31="Day Special",1.2,"NA"))) -> NA | AV31: ISATI GmbH
B32: =B31+1 -> 32 | C32: 28 | D32: N/A | E32: =E31+1 -> 28 | F32: =F31+1 -> 63 | G32: 28 | H32: N/A | I32: =I31+1 -> 59 | J32: =J31+1 -> 91 | K32: 28 | L32: N/A | M32: =M31+1 -> 87 | N32: =N31+1 -> 122 | O32: =O31+1 -> 28 | P32: Day | Q32: =Q31+1 -> 118 | R32: =R31+1 -> 152 | S32: =S31+1 -> 28 | T32: N/A | U32: =U31+1 -> 148 | V32: =V31+1 -> 183 | W32: =W31+1 -> 28 | X32: N/A | Y32: =Y31+1 -> 179 | AA32: =IF(D32="Day",1,IF(D32="1/2 Day",0.5,IF(D32="Day Special",1.2,"NA"))) -> NA | AB32: =IF(H32="Day",1,IF(H32="1/2 Day",0.5,IF(H32="Day Special",1.2,"NA"))) -> NA | AC32: =IF(L32="Day",1,IF(L32="1/2 Day",0.5,IF(L32="Day Special",1.2,"NA"))) -> NA | AD32: =IF(P32="Day",1,IF(P32="1/2 Day",0.5,IF(P32="Day Special",1.2,"NA"))) -> 1 | AE32: =IF(T32="Day",1,IF(T32="1/2 Day",0.5,IF(D32="Day Special",1.2,"NA"))) -> NA | AF32: =IF(X32="Day",1,IF(X32="1/2 Day",0.5,IF(X32="Day Special",1.2,"NA"))) -> NA
B33: =B32+1 -> 33 | C33: 29 | D33: N/A | E33: =E32+1 -> 29 | J33: =J32+1 -> 92 | K33: 29 | L33: N/A | M33: =M32+1 -> 88 | N33: =N32+1 -> 123 | O33: =O32+1 -> 29 | P33: Day | Q33: =Q32+1 -> 119 | R33: =R32+1 -> 153 | S33: =S32+1 -> 29 | T33: N/A | U33: =U32+1 -> 149 | V33: =V32+1 -> 184 | W33: =W32+1 -> 29 | X33: Day | Y33: =Y32+1 -> 180 | AA33: =IF(D33="Day",1,IF(D33="1/2 Day",0.5,IF(D33="Day Special",1.2,"NA"))) -> NA | AB33: =IF(H33="Day",1,IF(H33="1/2 Day",0.5,IF(H33="Day Special",1.2,"NA"))) -> 1 | AC33: =IF(L33="Day",1,IF(L33="1/2 Day",0.5,IF(L33="Day Special",1.2,"NA"))) -> NA | AD33: =IF(P33="Day",1,IF(P33="1/2 Day",0.5,IF(P33="Day Special",1.2,"NA"))) -> 1 | AE33: =IF(T33="Day",1,IF(T33="1/2 Day",0.5,IF(D33="Day Special",1.2,"NA"))) -> NA | AF33: =IF(X33="Day",1,IF(X33="1/2 Day",0.5,IF(X33="Day Special",1.2,"NA"))) -> 1
B34: =B33+1 -> 34 | C34: 30 | D34: N/A | E34: =E33+1 -> 30 | J34: =J33+1 -> 93 | K34: 30 | L34: Day | M34: =M33+1 -> 89 | N34: =N33+1 -> 124 | O34: =O33+1 -> 30 | P34: Day | Q34: =Q33+1 -> 120 | R34: =R33+1 -> 154 | S34: =S33+1 -> 30 | T34: N/A | U34: =U33+1 -> 150 | V34: =V33+1 -> 185 | W34: =W33+1 -> 30 | X34: Day | Y34: =Y33+1 -> 181 | AA34: =IF(D34="Day",1,IF(D34="1/2 Day",0.5,IF(D34="Day Special",1.2,"NA"))) -> NA | AC34: =IF(L34="Day",1,IF(L34="1/2 Day",0.5,IF(L34="Day Special",1.2,"NA"))) -> 1 | AD34: =IF(P34="Day",1,IF(P34="1/2 Day",0.5,IF(P34="Day Special",1.2,"NA"))) -> 1 | AE34: =IF(T34="Day",1,IF(T34="1/2 Day",0.5,IF(D34="Day Special",1.2,"NA"))) -> NA | AF34: =IF(X34="Day",1,IF(X34="1/2 Day",0.5,IF(X34="Day Special",1.2,"NA"))) -> 1
B35: =B34+1 -> 35 | C35: 31 | D35: N/A | E35: =E34+1 -> 31 | J35: =J34+1 -> 94 | K35: 31 | L35: Day | M35: =M34+1 -> 90 | R35: =R34+1 -> 155 | S35: =S34+1 -> 31 | T35: N/A | U35: =U34+1 -> 151 | AA35: =IF(D35="Day",1,IF(D35="1/2 Day",0.5,IF(D35="Day Special",1.2,"NA"))) -> NA | AC35: =IF(L35="Day",1,IF(L35="1/2 Day",0.5,IF(L35="Day Special",1.2,"NA"))) -> 1 | AE35: =IF(T35="Day",1,IF(T35="1/2 Day",0.5,IF(D35="Day Special",1.2,"NA"))) -> NA
B36: 21 | C36: Arbeitstage | F36: 20 | G36: Arbeitstage | J36: 22 | K36: Arbeitstage | N36: 19 | O36: Arbeitstage | R36: 19 | S36: Arbeitstage | V36: 22 | W36: Arbeitstage | Z36: Total Days | AA36: =SUM(AA5:AA35) -> 0 | AB36: =SUM(AB5:AB35) -> 1 | AC36: =SUM(AC5:AC35) -> 16 | AD36: =SUM(AD5:AD35) -> 20 | AE36: =SUM(AE5:AE35) -> 13 | AF36: =SUM(AF5:AF35) -> 16
J38: = Schulferien NW | P38: K = Kompensationstag | V38: =$V$36+$R$36+$N$36+$J$36+$F$36+$B$36+$B$72+$F$72+$J$72+$N$72+$R$72+$V$72 -> 255 | W38: Arbeitstage | AV38: - select -
AV39: ERS
B40: JULY | F40: AUGUST | J40: SEPTEMBER | N40: OCTOBER | R40: NOVEMBER | V40: DECEMBER | AA40: July | AB40: August | AC40: September | AD40: October | AE40: November | AF40: December | AV40: ERM
B41: =V34+1 -> 186 | C41: 1 | D41: N/A | E41: =Y34+1 -> 182 | F41: =B71+1 -> 217 | G41: 1 | H41: N/A | I41: =E71+1 -> 213 | J41: =F71+1 -> 248 | K41: =K40+1 -> 1 | L41: N/A | M41: =I71+1 -> 244 | N41: =J70+1 -> 278 | O41: 1 | P41: N/A | Q41: =M70+1 -> 274 | R41: =N71+1 -> 309 | S41: 1 | T41: N/A | U41: =Q71+1 -> 305 | V41: =R70+1 -> 339 | W41: 1 | X41: Day | Y41: =U70+1 -> 335 | AA41: =IF(D41="Day",1,IF(D41="1/2 Day",0.5,IF(D41="Day Special",1.2,"NA"))) -> NA | AB41: =IF(H41="Day",1,IF(H41="1/2 Day",0.5,IF(H41="Day Special",1.2,"NA"))) -> NA | AC41: =IF(L41="Day",1,IF(L41="1/2 Day",0.5,IF(L41="Day Special",1.2,"NA"))) -> NA | AD41: =IF(P41="Day",1,IF(P41="1/2 Day",0.5,IF(P41="Day Special",1.2,"NA"))) -> NA | AE41: =IF(T41="Day",1,IF(T41="1/2 Day",0.5,IF(T41="Day Special",1.2,"NA"))) -> NA | AF41: =IF(X41="Day",1,IF(X41="1/2 Day",0.5,IF(X41="Day Special",1.2,"NA"))) -> 1 | AV41: ER
B42: =B41+1 -> 187 | C42: =C41+1 -> 2 | D42: N/A | E42: =E41+1 -> 183 | F42: =F41+1 -> 218 | G42: =G41+1 -> 2 | H42: N/A | I42: =I41+1 -> 214 | J42: =J41+1 -> 249 | K42: =K41+1 -> 2 | L42: N/A | M42: =M41+1 -> 245 | N42: =N41+1 -> 279 | O42: =O41+1 -> 2 | P42: N/A | Q42: =Q41+1 -> 275 | R42: =R41+1 -> 310 | S42: =S41+1 -> 2 | T42: N/A | U42: =U41+1 -> 306 | V42: =V41+1 -> 340 | W42: =W41+1 -> 2 | X42: Day | Y42: =Y41+1 -> 336 | AA42: =IF(D42="Day",1,IF(D42="1/2 Day",0.5,IF(D42="Day Special",1.2,"NA"))) -> NA | AB42: =IF(H42="Day",1,IF(H42="1/2 Day",0.5,IF(H42="Day Special",1.2,"NA"))) -> NA | AC42: =IF(L42="Day",1,IF(L42="1/2 Day",0.5,IF(L42="Day Special",1.2,"NA"))) -> NA | AD42: =IF(P42="Day",1,IF(P42="1/2 Day",0.5,IF(P42="Day Special",1.2,"NA"))) -> NA | AE42: =IF(T42="Day",1,IF(T42="1/2 Day",0.5,IF(T42="Day Special",1.2,"NA"))) -> NA | AF42: =IF(X42="Day",1,IF(X42="1/2 Day",0.5,IF(X42="Day Special",1.2,"NA"))) -> 1 | AV42: EXI
B43: =B42+1 -> 188 | C43: =C42+1 -> 3 | D43: N/A | E43: =E42+1 -> 184 | F43: =F42+1 -> 219 | G43: =G42+1 -> 3 | H43: N/A | I43: =I42+1 -> 215 | J43: =J42+1 -> 250 | K43: =K42+1 -> 3 | L43: N/A | M43: =M42+1 -> 246 | N43: =N42+1 -> 280 | O43: =O42+1 -> 3 | P43: N/A | Q43: =Q42+1 -> 276 | R43: =R42+1 -> 311 | S43: =S42+1 -> 3 | T43: N/A | U43: =U42+1 -> 307 | V43: =V42+1 -> 341 | W43: =W42+1 -> 3 | X43: N/A | Y43: =Y42+1 -> 337 | AA43: =IF(D43="Day",1,IF(D43="1/2 Day",0.5,IF(D43="Day Special",1.2,"NA"))) -> NA | AB43: =IF(H43="Day",1,IF(H43="1/2 Day",0.5,IF(H43="Day Special",1.2,"NA"))) -> NA | AC43: =IF(L43="Day",1,IF(L43="1/2 Day",0.5,IF(L43="Day Special",1.2,"NA"))) -> NA | AD43: =IF(P43="Day",1,IF(P43="1/2 Day",0.5,IF(P43="Day Special",1.2,"NA"))) -> NA | AE43: =IF(T43="Day",1,IF(T43="1/2 Day",0.5,IF(T43="Day Special",1.2,"NA"))) -> NA | AF43: =IF(X43="Day",1,IF(X43="1/2 Day",0.5,IF(X43="Day Special",1.2,"NA"))) -> NA | AV43: ETE
B44: =B43+1 -> 189 | C44: =C43+1 -> 4 | D44: N/A | E44: =E43+1 -> 185 | F44: =F43+1 -> 220 | G44: =G43+1 -> 4 | H44: N/A | I44: =I43+1 -> 216 | J44: =J43+1 -> 251 | K44: =K43+1 -> 4 | L44: N/A | M44: =M43+1 -> 247 | N44: =N43+1 -> 281 | O44: =O43+1 -> 4 | P44: N/A | Q44: =Q43+1 -> 277 | R44: =R43+1 -> 312 | S44: =S43+1 -> 4 | T44: N/A | U44: =U43+1 -> 308 | V44: =V43+1 -> 342 | W44: =W43+1 -> 4 | X44: N/A | Y44: =Y43+1 -> 338 | AA44: =IF(D44="Day",1,IF(D44="1/2 Day",0.5,IF(D44="Day Special",1.2,"NA"))) -> NA | AB44: =IF(H44="Day",1,IF(H44="1/2 Day",0.5,IF(H44="Day Special",1.2,"NA"))) -> NA | AC44: =IF(L44="Day",1,IF(L44="1/2 Day",0.5,IF(L44="Day Special",1.2,"NA"))) -> NA | AD44: =IF(P44="Day",1,IF(P44="1/2 Day",0.5,IF(P44="Day Special",1.2,"NA"))) -> NA | AE44: =IF(T44="Day",1,IF(T44="1/2 Day",0.5,IF(T44="Day Special",1.2,"NA"))) -> NA | AF44: =IF(X44="Day",1,IF(X44="1/2 Day",0.5,IF(X44="Day Special",1.2,"NA"))) -> NA | AV44: ETM
B45: =B44+1 -> 190 | C45: =C44+1 -> 5 | D45: N/A | E45: =E44+1 -> 186 | F45: =F44+1 -> 221 | G45: =G44+1 -> 5 | H45: N/A | I45: =I44+1 -> 217 | J45: =J44+1 -> 252 | K45: =K44+1 -> 5 | L45: N/A | M45: =M44+1 -> 248 | N45: =N44+1 -> 282 | O45: =O44+1 -> 5 | P45: N/A | Q45: =Q44+1 -> 278 | R45: =R44+1 -> 313 | S45: =S44+1 -> 5 | T45: N/A | U45: =U44+1 -> 309 | V45: =V44+1 -> 343 | W45: =W44+1 -> 5 | X45: N/A | Y45: =Y44+1 -> 339 | AA45: =IF(D45="Day",1,IF(D45="1/2 Day",0.5,IF(D45="Day Special",1.2,"NA"))) -> NA | AB45: =IF(H45="Day",1,IF(H45="1/2 Day",0.5,IF(H45="Day Special",1.2,"NA"))) -> NA | AC45: =IF(L45="Day",1,IF(L45="1/2 Day",0.5,IF(L45="Day Special",1.2,"NA"))) -> NA | AD45: =IF(P45="Day",1,IF(P45="1/2 Day",0.5,IF(P45="Day Special",1.2,"NA"))) -> NA | AE45: =IF(T45="Day",1,IF(T45="1/2 Day",0.5,IF(T45="Day Special",1.2,"NA"))) -> NA | AF45: =IF(X45="Day",1,IF(X45="1/2 Day",0.5,IF(X45="Day Special",1.2,"NA"))) -> NA | AV45: EXE
B46: =B45+1 -> 191 | C46: =C45+1 -> 6 | D46: N/A | E46: =E45+1 -> 187 | F46: =F45+1 -> 222 | G46: =G45+1 -> 6 | H46: N/A | I46: =I45+1 -> 218 | J46: =J45+1 -> 253 | K46: =K45+1 -> 6 | L46: N/A | M46: =M45+1 -> 249 | N46: =N45+1 -> 283 | O46: =O45+1 -> 6 | P46: N/A | Q46: =Q45+1 -> 279 | R46: =R45+1 -> 314 | S46: =S45+1 -> 6 | T46: N/A | U46: =U45+1 -> 310 | V46: =V45+1 -> 344 | W46: =W45+1 -> 6 | X46: N/A | Y46: =Y45+1 -> 340 | AA46: =IF(D46="Day",1,IF(D46="1/2 Day",0.5,IF(D46="Day Special",1.2,"NA"))) -> NA | AB46: =IF(H46="Day",1,IF(H46="1/2 Day",0.5,IF(H46="Day Special",1.2,"NA"))) -> NA | AC46: =IF(L46="Day",1,IF(L46="1/2 Day",0.5,IF(L46="Day Special",1.2,"NA"))) -> NA | AD46: =IF(P46="Day",1,IF(P46="1/2 Day",0.5,IF(P46="Day Special",1.2,"NA"))) -> NA | AE46: =IF(T46="Day",1,IF(T46="1/2 Day",0.5,IF(T46="Day Special",1.2,"NA"))) -> NA | AF46: =IF(X46="Day",1,IF(X46="1/2 Day",0.5,IF(X46="Day Special",1.2,"NA"))) -> NA | AV46: ETE
B47: =B46+1 -> 192 | C47: =C46+1 -> 7 | D47: N/A | E47: =E46+1 -> 188 | F47: =F46+1 -> 223 | G47: =G46+1 -> 7 | H47: N/A | I47: =I46+1 -> 219 | J47: =J46+1 -> 254 | K47: =K46+1 -> 7 | L47: N/A | M47: =M46+1 -> 250 | N47: =N46+1 -> 284 | O47: =O46+1 -> 7 | P47: N/A | Q47: =Q46+1 -> 280 | R47: =R46+1 -> 315 | S47: =S46+1 -> 7 | T47: N/A | U47: =U46+1 -> 311 | V47: =V46+1 -> 345 | W47: =W46+1 -> 7 | X47: N/A | Y47: =Y46+1 -> 341 | AA47: =IF(D47="Day",1,IF(D47="1/2 Day",0.5,IF(D47="Day Special",1.2,"NA"))) -> NA | AB47: =IF(H47="Day",1,IF(H47="1/2 Day",0.5,IF(H47="Day Special",1.2,"NA"))) -> NA | AC47: =IF(L47="Day",1,IF(L47="1/2 Day",0.5,IF(L47="Day Special",1.2,"NA"))) -> NA | AD47: =IF(P47="Day",1,IF(P47="1/2 Day",0.5,IF(P47="Day Special",1.2,"NA"))) -> NA | AE47: =IF(T47="Day",1,IF(T47="1/2 Day",0.5,IF(T47="Day Special",1.2,"NA"))) -> NA | AF47: =IF(X47="Day",1,IF(X47="1/2 Day",0.5,IF(X47="Day Special",1.2,"NA"))) -> NA | AV47: EZ
B48: =B47+1 -> 193 | C48: =C47+1 -> 8 | D48: N/A | E48: =E47+1 -> 189 | F48: =F47+1 -> 224 | G48: =G47+1 -> 8 | H48: N/A | I48: =I47+1 -> 220 | J48: =J47+1 -> 255 | K48: =K47+1 -> 8 | L48: N/A | M48: =M47+1 -> 251 | N48: =N47+1 -> 285 | O48: =O47+1 -> 8 | P48: N/A | Q48: =Q47+1 -> 281 | R48: =R47+1 -> 316 | S48: =S47+1 -> 8 | T48: N/A | U48: =U47+1 -> 312 | V48: =V47+1 -> 346 | W48: =W47+1 -> 8 | X48: N/A | Y48: =Y47+1 -> 342 | AA48: =IF(D48="Day",1,IF(D48="1/2 Day",0.5,IF(D48="Day Special",1.2,"NA"))) -> NA | AB48: =IF(H48="Day",1,IF(H48="1/2 Day",0.5,IF(H48="Day Special",1.2,"NA"))) -> NA | AC48: =IF(L48="Day",1,IF(L48="1/2 Day",0.5,IF(L48="Day Special",1.2,"NA"))) -> NA | AD48: =IF(P48="Day",1,IF(P48="1/2 Day",0.5,IF(P48="Day Special",1.2,"NA"))) -> NA | AE48: =IF(T48="Day",1,IF(T48="1/2 Day",0.5,IF(T48="Day Special",1.2,"NA"))) -> NA | AF48: =IF(X48="Day",1,IF(X48="1/2 Day",0.5,IF(X48="Day Special",1.2,"NA"))) -> NA | AV48: EZV
B49: =B48+1 -> 194 | C49: =C48+1 -> 9 | D49: N/A | E49: =E48+1 -> 190 | F49: =F48+1 -> 225 | G49: =G48+1 -> 9 | H49: N/A | I49: =I48+1 -> 221 | J49: =J48+1 -> 256 | K49: =K48+1 -> 9 | L49: N/A | M49: =M48+1 -> 252 | N49: =N48+1 -> 286 | O49: =O48+1 -> 9 | P49: N/A | Q49: =Q48+1 -> 282 | R49: =R48+1 -> 317 | S49: =S48+1 -> 9 | T49: N/A | U49: =U48+1 -> 313 | V49: =V48+1 -> 347 | W49: =W48+1 -> 9 | X49: N/A | Y49: =Y48+1 -> 343 | AA49: =IF(D49="Day",1,IF(D49="1/2 Day",0.5,IF(D49="Day Special",1.2,"NA"))) -> NA | AB49: =IF(H49="Day",1,IF(H49="1/2 Day",0.5,IF(H49="Day Special",1.2,"NA"))) -> NA | AC49: =IF(L49="Day",1,IF(L49="1/2 Day",0.5,IF(L49="Day Special",1.2,"NA"))) -> NA | AD49: =IF(P49="Day",1,IF(P49="1/2 Day",0.5,IF(P49="Day Special",1.2,"NA"))) -> NA | AE49: =IF(T49="Day",1,IF(T49="1/2 Day",0.5,IF(T49="Day Special",1.2,"NA"))) -> NA | AF49: =IF(X49="Day",1,IF(X49="1/2 Day",0.5,IF(X49="Day Special",1.2,"NA"))) -> NA | AV49: EZC
B50: =B49+1 -> 195 | C50: =C49+1 -> 10 | D50: N/A | E50: =E49+1 -> 191 | F50: =F49+1 -> 226 | G50: =G49+1 -> 10 | H50: N/A | I50: =I49+1 -> 222 | J50: =J49+1 -> 257 | K50: =K49+1 -> 10 | L50: N/A | M50: =M49+1 -> 253 | N50: =N49+1 -> 287 | O50: =O49+1 -> 10 | P50: N/A | Q50: =Q49+1 -> 283 | R50: =R49+1 -> 318 | S50: =S49+1 -> 10 | T50: N/A | U50: =U49+1 -> 314 | V50: =V49+1 -> 348 | W50: =W49+1 -> 10 | X50: N/A | Y50: =Y49+1 -> 344 | AA50: =IF(D50="Day",1,IF(D50="1/2 Day",0.5,IF(D50="Day Special",1.2,"NA"))) -> NA | AB50: =IF(H50="Day",1,IF(H50="1/2 Day",0.5,IF(H50="Day Special",1.2,"NA"))) -> NA | AC50: =IF(L50="Day",1,IF(L50="1/2 Day",0.5,IF(L50="Day Special",1.2,"NA"))) -> NA | AD50: =IF(P50="Day",1,IF(P50="1/2 Day",0.5,IF(P50="Day Special",1.2,"NA"))) -> NA | AE50: =IF(T50="Day",1,IF(T50="1/2 Day",0.5,IF(T50="Day Special",1.2,"NA"))) -> NA | AF50: =IF(X50="Day",1,IF(X50="1/2 Day",0.5,IF(X50="Day Special",1.2,"NA"))) -> NA | AV50: ENT
...

Sheet Print January Summary
B2: =+'Work Report Consultant'!B2 -> Consultant work report 2026 | G2: ANAVIA AG
B3: =+'Work Report Consultant'!B3 -> Name: | C3: =+'Work Report Consultant'!E3 -> Jorge Benito Sanabrias
B4: =+'Work Report Consultant'!P3 -> 0 | C4: =+'Work Report Consultant'!R3 -> Anzen Engineering Switzerland
B6: =+'Work Report Consultant'!B4 -> JANUARY | C6: =+'Work Report Consultant'!AV3 -> 2026 | F6: Comments
B7: =+'Work Report Consultant'!B5 -> 5 | C7: =+'Work Report Consultant'!C5 -> 1 | D7: =+'Work Report Consultant'!D5 -> Neujahr | E7: =+'Work Report Consultant'!AA5 -> NA
B8: =B7+1 -> 6 | C8: =+'Work Report Consultant'!C6 -> 2 | D8: =+'Work Report Consultant'!D6 -> N/A | E8: =+'Work Report Consultant'!AA6 -> NA
B9: =B8+1 -> 7 | C9: =+'Work Report Consultant'!C7 -> 3 | D9: =+'Work Report Consultant'!D7 -> N/A | E9: =+'Work Report Consultant'!AA7 -> NA
B10: =B9+1 -> 8 | C10: =+'Work Report Consultant'!C8 -> 4 | D10: =+'Work Report Consultant'!D8 -> N/A | E10: =+'Work Report Consultant'!AA8 -> NA
B11: =B10+1 -> 9 | C11: =+'Work Report Consultant'!C9 -> 5 | D11: =+'Work Report Consultant'!D9 -> N/A | E11: =+'Work Report Consultant'!AA9 -> NA
B12: =B11+1 -> 10 | C12: =+'Work Report Consultant'!C10 -> 6 | D12: =+'Work Report Consultant'!D10 -> N/A | E12: =+'Work Report Consultant'!AA10 -> NA
B13: =B12+1 -> 11 | C13: =+'Work Report Consultant'!C11 -> 7 | D13: =+'Work Report Consultant'!D11 -> N/A | E13: =+'Work Report Consultant'!AA11 -> NA
B14: =B13+1 -> 12 | C14: =+'Work Report Consultant'!C12 -> 8 | D14: =+'Work Report Consultant'!D12 -> N/A | E14: =+'Work Report Consultant'!AA12 -> NA
B15: =B14+1 -> 13 | C15: =+'Work Report Consultant'!C13 -> 9 | D15: =+'Work Report Consultant'!D13 -> N/A | E15: =+'Work Report Consultant'!AA13 -> NA
B16: =B15+1 -> 14 | C16: =+'Work Report Consultant'!C14 -> 10 | D16: =+'Work Report Consultant'!D14 -> N/A | E16: =+'Work Report Consultant'!AA14 -> NA
B17: =B16+1 -> 15 | C17: =+'Work Report Consultant'!C15 -> 11 | D17: =+'Work Report Consultant'!D15 -> N/A | E17: =+'Work Report Consultant'!AA15 -> NA
B18: =B17+1 -> 16 | C18: =+'Work Report Consultant'!C16 -> 12 | D18: =+'Work Report Consultant'!D16 -> N/A | E18: =+'Work Report Consultant'!AA16 -> NA
B19: =B18+1 -> 17 | C19: =+'Work Report Consultant'!C17 -> 13 | D19: =+'Work Report Consultant'!D17 -> N/A | E19: =+'Work Report Consultant'!AA17 -> NA
... B37: =B36+1 -> 35 | C37: =+'Work Report Consultant'!C35 -> 31 | D37: =+'Work Report Consultant'!D35 -> N/A | E37: =+'Work Report Consultant'!AA35 -> NA
B39: Total Working Days | E39: =SUM(E7:E37) -> 0 | F39: to be invoiced
B42: Summary of Days and associated booking numbers*
B44: Number of Days | D44: Netzplan/Auftrag | E44: Vorgang | F44: Element | G44: Project Name
B45: xxx | D45: 9xxxxx | E45: xxxx | F45: xxxx
B46: xxx | D46: 9xxxxx | E46: xxxx | F46: xxxx
B47: xxx | D47: 9xxxxx | E47: xxxx | F47: xxxx
B48: xxx | D48: 9xxxxx | E48: xxxx | F48: xxxx
B49: xxx | D49: 9xxxxx | E49: xxxx | F49: xxxx
B50: xxx | D50: 9xxxxx | E50: xxxx | F50: xxxx
B51: xxx | D51: 9xxxxx | E51: xxxx | F51: xxxx
B53: *it is mandatory to enter the booking numbers - please review with the team leader!
B54: Send the signed work report to your company at the month end.
B55: Invoices from the consultant company will only be accepted with a signed work report.
B57: Date & Signature Consultant
B59: Department / Team Leader Name | F59: Department:_______TL/Name__________________
B60: Date & Signature Team Leader

Sheet Print February Summary 
B2: =+'Work Report Consultant'!B2 -> Consultant work report 2026 | G2: ANAVIA AG
B3: =+'Work Report Consultant'!B3 -> Name: | C3: =+'Work Report Consultant'!E3 -> Jorge Benito Sanabrias
B4: =+'Work Report Consultant'!P3 -> 0 | C4: =+'Work Report Consultant'!R3 -> Anzen Engineering Switzerland
B6: =+'Work Report Consultant'!F4 -> FEBRUARY | C6: =+'Work Report Consultant'!AV3 -> 2026 | F6: Comments
B7: =+'Print January Summary'!B37+1 -> 36 | C7: =+'Work Report Consultant'!G5 -> 1 | D7: =+'Work Report Consultant'!H5 -> N/A | E7: =+'Work Report Consultant'!AB5 -> NA
B8: =+B7+1 -> 37 | C8: =+'Work Report Consultant'!G6 -> 2 | D8: =+'Work Report Consultant'!H6 -> N/A | E8: =+'Work Report Consultant'!AB6 -> NA
B9: =+B8+1 -> 38 | C9: =+'Work Report Consultant'!G7 -> 4 | D9: =+'Work Report Consultant'!H7 -> N/A | E9: =+'Work Report Consultant'!AB7 -> NA
B10: =+B9+1 -> 39 | C10: =+'Work Report Consultant'!G8 -> 4 | D10: =+'Work Report Consultant'!H8 -> N/A | E10: =+'Work Report Consultant'!AB8 -> NA
B11: =+B10+1 -> 40 | C11: =+'Work Report Consultant'!G9 -> 5 | D11: =+'Work Report Consultant'!H9 -> N/A | E11: =+'Work Report Consultant'!AB9 -> NA
B12: =+B11+1 -> 41 | C12: =+'Work Report Consultant'!G10 -> 6 | D12: =+'Work Report Consultant'!H10 -> N/A | E12: =+'Work Report Consultant'!AB10 -> NA
B13: =+B12+1 -> 42 | C13: =+'Work Report Consultant'!G11 -> 7 | D13: =+'Work Report Consultant'!H11 -> N/A | E13: =+'Work Report Consultant'!AB11 -> NA
B14: =+B13+1 -> 43 | C14: =+'Work Report Consultant'!G12 -> 8 | D14: =+'Work Report Consultant'!H12 -> N/A | E14: =+'Work Report Consultant'!AB12 -> NA
B15: =+B14+1 -> 44 | C15: =+'Work Report Consultant'!G13 -> 9 | D15: =+'Work Report Consultant'!H13 -> N/A | E15: =+'Work Report Consultant'!AB13 -> NA
B16: =+B15+1 -> 45 | C16: =+'Work Report Consultant'!G14 -> 10 | D16: =+'Work Report Consultant'!H14 -> N/A | E16: =+'Work Report Consultant'!AB14 -> NA
B17: =+B16+1 -> 46 | C17: =+'Work Report Consultant'!G15 -> 11 | D17: =+'Work Report Consultant'!H15 -> N/A | E17: =+'Work Report Consultant'!AB15 -> NA
B18: =+B17+1 -> 47 | C18: =+'Work Report Consultant'!G16 -> 12 | D18: =+'Work Report Consultant'!H16 -> N/A | E18: =+'Work Report Consultant'!AB16 -> NA
B19: =+B18+1 -> 48 | C19: =+'Work Report Consultant'!G17 -> 13 | D19: =+'Work Report Consultant'!H17 -> N/A | E19: =+'Work Report Consultant'!AB17 -> NA
... B35: =+B34+1 -> 64 | C35: =+'Work Report Consultant'!G33 -> 0 | D35: =+'Work Report Consultant'!H33 -> 0 | E35: =+'Work Report Consultant'!AB33 -> 1
B39: Total Working Days | E39: =SUM(E7:E37) -> 1 | F39: to be invoiced
B42: Summary of Days and associated booking numbers*
B44: Number of Days | D44: Netzplan/Auftrag | E44: Vorgang | F44: Element | G44: Project Name
B45: xxx | D45: 9xxxxx | E45: xxxx | F45: xxxx
B46: xxx | D46: 9xxxxx | E46: xxxx | F46: xxxx
B47: xxx | D47: 9xxxxx | E47: xxxx | F47: xxxx
B48: xxx | D48: 9xxxxx | E48: xxxx | F48: xxxx
B49: xxx | D49: 9xxxxx | E49: xxxx | F49: xxxx
B50: xxx | D50: 9xxxxx | E50: xxxx | F50: xxxx
B51: xxx | D51: 9xxxxx | E51: xxxx | F51: xxxx
B53: *it is mandatory to enter the booking numbers - please review with the team leader!
B54: Send the signed work report to your company at the month end.
B55: Invoices from the consultant company will only be accepted with a signed work report.
B57: Date & Signature Contractor
B59: Department / Team Leader Name | F59: Department:_______TL/Name__________________
B60: Date & Signature Team Leader

Sheet Print March Summary
B2: =+'Work Report Consultant'!B2 -> Consultant work report 2026 | G2: ANAVIA AG
B3: =+'Work Report Consultant'!B3 -> Name: | C3: =+'Work Report Consultant'!E3 -> Jorge Benito Sanabrias
B4: =+'Work Report Consultant'!P3 -> 0 | C4: =+'Work Report Consultant'!R3 -> Anzen Engineering Switzerland
B6: =+'Work Report Consultant'!J4 -> MARCH | C6: =+'Work Report Consultant'!AV3 -> 2026 | F6: Comments
B7: =+'Work Report Consultant'!J5 -> 64 | C7: =+'Work Report Consultant'!K5 -> 1 | D7: =+'Work Report Consultant'!L5 -> N/A | E7: =+'Work Report Consultant'!AC5 -> NA
B8: =+B7+1 -> 65 | C8: =+'Work Report Consultant'!K6 -> 2 | D8: =+'Work Report Consultant'!L6 -> N/A | E8: =+'Work Report Consultant'!AC6 -> NA
B9: =+B8+1 -> 66 | C9: =+'Work Report Consultant'!K7 -> 3 | D9: =+'Work Report Consultant'!L7 -> N/A | E9: =+'Work Report Consultant'!AC7 -> NA
B10: =+B9+1 -> 67 | C10: =+'Work Report Consultant'!K8 -> 4 | D10: =+'Work Report Consultant'!L8 -> N/A | E10: =+'Work Report Consultant'!AC8 -> NA
B11: =+B10+1 -> 68 | C11: =+'Work Report Consultant'!K9 -> 5 | D11: =+'Work Report Consultant'!L9 -> N/A | E11: =+'Work Report Consultant'!AC9 -> NA
B12: =+B11+1 -> 69 | C12: =+'Work Report Consultant'!K10 -> 6 | D12: =+'Work Report Consultant'!L10 -> N/A | E12: =+'Work Report Consultant'!AC10 -> NA
B13: =+B12+1 -> 70 | C13: =+'Work Report Consultant'!K11 -> 7 | D13: =+'Work Report Consultant'!L11 -> N/A | E13: =+'Work Report Consultant'!AC11 -> NA
B14: =+B13+1 -> 71 | C14: =+'Work Report Consultant'!K12 -> 8 | D14: =+'Work Report Consultant'!L12 -> N/A | E14: =+'Work Report Consultant'!AC12 -> NA
B15: =+B14+1 -> 72 | C15: =+'Work Report Consultant'!K13 -> 9 | D15: =+'Work Report Consultant'!L13 -> N/A | E15: =+'Work Report Consultant'!AC13 -> NA
B16: =+B15+1 -> 73 | C16: =+'Work Report Consultant'!K14 -> 10 | D16: =+'Work Report Consultant'!L14 -> Day | E16: =+'Work Report Consultant'!AC14 -> 1
B17: =+B16+1 -> 74 | C17: =+'Work Report Consultant'!K15 -> 11 | D17: =+'Work Report Consultant'!L15 -> Day | E17: =+'Work Report Consultant'!AC15 -> 1
B18: =+B17+1 -> 75 | C18: =+'Work Report Consultant'!K16 -> 12 | D18: =+'Work Report Consultant'!L16 -> Day | E18: =+'Work Report Consultant'!AC16 -> 1
B19: =+B18+1 -> 76 | C19: =+'Work Report Consultant'!K17 -> 13 | D19: =+'Work Report Consultant'!L17 -> Day | E19: =+'Work Report Consultant'!AC17 -> 1
... B37: =+B36+1 -> 94 | C37: =+'Work Report Consultant'!K35 -> 31 | D37: =+'Work Report Consultant'!L35 -> Day | E37: =+'Work Report Consultant'!AC35 -> 1
B39: Total Working Days | E39: =SUM(E7:E37) -> 16 | F39: to be invoiced
B42: Summary of Days and associated booking numbers*
B44: Number of Days | D44: Netzplan/Auftrag | E44: Vorgang | F44: Element | G44: Project Name
B45: xxx | D45: 9xxxxx | E45: xxxx | F45: xxxx
B46: xxx | D46: 9xxxxx | E46: xxxx | F46: xxxx
B47: xxx | D47: 9xxxxx | E47: xxxx | F47: xxxx
B48: xxx | D48: 9xxxxx | E48: xxxx | F48: xxxx
B49: xxx | D49: 9xxxxx | E49: xxxx | F49: xxxx
B50: xxx | D50: 9xxxxx | E50: xxxx | F50: xxxx
B51: xxx | D51: 9xxxxx | E51: xxxx | F51: xxxx
B53: *it is mandatory to enter the booking numbers - please review with the team leader!
B54: Send the signed work report to your company at the month end.
B55: Invoices from the consultant company will only be accepted with a signed work report.
B57: Date & Signature Contractor
B59: Department / Team Leader Name | F59: Department:_______TL/Name__________________
B60: Date & Signature Team Leader

Sheet Print April Summary
B2: =+'Work Report Consultant'!B2 -> Consultant work report 2026 | G2: ANAVIA AG
B3: =+'Work Report Consultant'!B3 -> Name: | C3: =+'Work Report Consultant'!E3 -> Jorge Benito Sanabrias
B4: =+'Work Report Consultant'!P3 -> 0 | C4: =+'Work Report Consultant'!R3 -> Anzen Engineering Switzerland
B6: =+'Work Report Consultant'!N4 -> APRIL | C6: =+'Work Report Consultant'!AV3 -> 2026 | F6: Comments
B7: =+'Print March Summary'!B37+1 -> 95 | C7: =+'Work Report Consultant'!O5 -> 1 | D7: =+'Work Report Consultant'!P5 -> Day | E7: =+'Work Report Consultant'!AD5 -> 1
B8: =+B7+1 -> 96 | C8: =+'Work Report Consultant'!O6 -> 2 | D8: =+'Work Report Consultant'!P6 -> Day | E8: =+'Work Report Consultant'!AD6 -> 1
B9: =+B8+1 -> 97 | C9: =+'Work Report Consultant'!O7 -> 3 | D9: =+'Work Report Consultant'!P7 -> Karfreitag | E9: =+'Work Report Consultant'!AD7 -> NA
B10: =+B9+1 -> 98 | C10: =+'Work Report Consultant'!O8 -> 4 | D10: =+'Work Report Consultant'!P8 -> N/A | E10: =+'Work Report Consultant'!AD8 -> NA
B11: =+B10+1 -> 99 | C11: =+'Work Report Consultant'!O9 -> 5 | D11: =+'Work Report Consultant'!P9 -> Ostern | E11: =+'Work Report Consultant'!AD9 -> NA
B12: =+B11+1 -> 100 | C12: =+'Work Report Consultant'!O10 -> 6 | D12: =+'Work Report Consultant'!P10 -> Ostermontag | E12: =+'Work Report Consultant'!AD10 -> NA
B13: =+B12+1 -> 101 | C13: =+'Work Report Consultant'!O11 -> 7 | D13: =+'Work Report Consultant'!P11 -> Day | E13: =+'Work Report Consultant'!AD11 -> 1
B14: =+B13+1 -> 102 | C14: =+'Work Report Consultant'!O12 -> 8 | D14: =+'Work Report Consultant'!P12 -> Day | E14: =+'Work Report Consultant'!AD12 -> 1
B15: =+B14+1 -> 103 | C15: =+'Work Report Consultant'!O13 -> 9 | D15: =+'Work Report Consultant'!P13 -> Day | E15: =+'Work Report Consultant'!AD13 -> 1
B16: =+B15+1 -> 104 | C16: =+'Work Report Consultant'!O14 -> 10 | D16: =+'Work Report Consultant'!P14 -> Day | E16: =+'Work Report Consultant'!AD14 -> 1
B17: =+B16+1 -> 105 | C17: =+'Work Report Consultant'!O15 -> 11 | D17: =+'Work Report Consultant'!P15 -> N/A | E17: =+'Work Report Consultant'!AD15 -> NA
B18: =+B17+1 -> 106 | C18: =+'Work Report Consultant'!O16 -> 12 | D18: =+'Work Report Consultant'!P16 -> N/A | E18: =+'Work Report Consultant'!AD16 -> NA
B19: =+B18+1 -> 107 | C19: =+'Work Report Consultant'!O17 -> 13 | D19: =+'Work Report Consultant'!P17 -> Day | E19: =+'Work Report Consultant'!AD17 -> 1
... B36: =+B35+1 -> 124 | C36: =+'Work Report Consultant'!O34 -> 30 | D36: =+'Work Report Consultant'!P34 -> Day | E36: =+'Work Report Consultant'!AD34 -> 1
B39: Total Working Days | E39: =SUM(E7:E37) -> 20 | F39: to be invoiced
B42: Summary of Days and associated booking numbers*
B44: Number of Days | D44: Netzplan/Auftrag | E44: Vorgang | F44: Element | G44: Project Name
B45: xxx | D45: 9xxxxx | E45: xxxx | F45: xxxx
B46: xxx | D46: 9xxxxx | E46: xxxx | F46: xxxx
B47: xxx | D47: 9xxxxx | E47: xxxx | F47: xxxx
B48: xxx | D48: 9xxxxx | E48: xxxx | F48: xxxx
B49: xxx | D49: 9xxxxx | E49: xxxx | F49: xxxx
B50: xxx | D50: 9xxxxx | E50: xxxx | F50: xxxx
B51: xxx | D51: 9xxxxx | E51: xxxx | F51: xxxx
B53: *it is mandatory to enter the booking numbers - please review with the team leader!
B54: Send the signed work report to your company at the month end.
B55: Invoices from the consultant company will only be accepted with a signed work report.
B57: Date & Signature Contractor
B59: Department / Team Leader Name | F59: Department:_______TL/Name__________________
B60: Date & Signature Team Leader

Sheet Print May Summary
B2: =+'Work Report Consultant'!B2 -> Consultant work report 2026 | G2: ANAVIA AG
B3: =+'Work Report Consultant'!B3 -> Name: | C3: =+'Work Report Consultant'!E3 -> Jorge Benito Sanabrias
B4: =+'Work Report Consultant'!P3 -> 0 | C4: =+'Work Report Consultant'!R3 -> Anzen Engineering Switzerland
B6: =+'Work Report Consultant'!R4 -> MAY | C6: =+'Work Report Consultant'!AV3 -> 2026 | F6: Comments
B7: =+'Print April Summary'!B36+1 -> 125 | C7: =+'Work Report Consultant'!S5 -> 1 | D7: =+'Work Report Consultant'!T5 -> Day | E7: =+'Work Report Consultant'!AE5 -> 1
B8: =+B7+1 -> 126 | C8: =+'Work Report Consultant'!S6 -> 2 | D8: =+'Work Report Consultant'!T6 -> N/A | E8: =+'Work Report Consultant'!AE6 -> NA
B9: =+B8+1 -> 127 | C9: =+'Work Report Consultant'!S7 -> 3 | D9: =+'Work Report Consultant'!T7 -> N/A | E9: =+'Work Report Consultant'!AE7 -> NA
B10: =+B9+1 -> 128 | C10: =+'Work Report Consultant'!S8 -> 4 | D10: =+'Work Report Consultant'!T8 -> Day | E10: =+'Work Report Consultant'!AE8 -> 1
B11: =+B10+1 -> 129 | C11: =+'Work Report Consultant'!S9 -> 5 | D11: =+'Work Report Consultant'!T9 -> Day | E11: =+'Work Report Consultant'!AE9 -> 1
B12: =+B11+1 -> 130 | C12: =+'Work Report Consultant'!S10 -> 6 | D12: =+'Work Report Consultant'!T10 -> Day | E12: =+'Work Report Consultant'!AE10 -> 1 | F12: +2 h
B13: =+B12+1 -> 131 | C13: =+'Work Report Consultant'!S11 -> 7 | D13: =+'Work Report Consultant'!T11 -> Day | E13: =+'Work Report Consultant'!AE11 -> 1
B14: =+B13+1 -> 132 | C14: =+'Work Report Consultant'!S12 -> 8 | D14: =+'Work Report Consultant'!T12 -> Day | E14: =+'Work Report Consultant'!AE12 -> 1
B15: =+B14+1 -> 133 | C15: =+'Work Report Consultant'!S13 -> 9 | D15: =+'Work Report Consultant'!T13 -> N/A | E15: =+'Work Report Consultant'!AE13 -> NA
B16: =+B15+1 -> 134 | C16: =+'Work Report Consultant'!S14 -> 10 | D16: =+'Work Report Consultant'!T14 -> N/A | E16: =+'Work Report Consultant'!AE14 -> NA
B17: =+B16+1 -> 135 | C17: =+'Work Report Consultant'!S15 -> 11 | D17: =+'Work Report Consultant'!T15 -> Day | E17: =+'Work Report Consultant'!AE15 -> 1
B18: =+B17+1 -> 136 | C18: =+'Work Report Consultant'!S16 -> 12 | D18: =+'Work Report Consultant'!T16 -> Day | E18: =+'Work Report Consultant'!AE16 -> 1
B19: =+B18+1 -> 137 | C19: =+'Work Report Consultant'!S17 -> 13 | D19: =+'Work Report Consultant'!T17 -> Day | E19: =+'Work Report Consultant'!AE17 -> 1
B20: =+B19+1 -> 138 | C20: =+'Work Report Consultant'!S18 -> 14 | D20: =+'Work Report Consultant'!T18 -> Himmelfahrt | E20: =+'Work Report Consultant'!AE18 -> NA
B21: =+B20+1 -> 139 | C21: =+'Work Report Consultant'!S19 -> 15 | D21: =+'Work Report Consultant'!T19 -> Holiday | E21: =+'Work Report Consultant'!AE19 -> NA
B22: =+B21+1 -> 140 | C22: =+'Work Report Consultant'!S20 -> 16 | D22: =+'Work Report Consultant'!T20 -> N/A | E22: =+'Work Report Consultant'!AE20 -> NA
B23: =+B22+1 -> 141 | C23: =+'Work Report Consultant'!S21 -> 17 | D23: =+'Work Report Consultant'!T21 -> N/A | E23: =+'Work Report Consultant'!AE21 -> NA
B24: =+B23+1 -> 142 | C24: =+'Work Report Consultant'!S22 -> 18 | D24: =+'Work Report Consultant'!T22 -> Holiday | E24: =+'Work Report Consultant'!AE22 -> NA
... B37: =+B36+1 -> 155 | C37: =+'Work Report Consultant'!S35 -> 31 | D37: =+'Work Report Consultant'!T35 -> N/A | E37: =+'Work Report Consultant'!AE35 -> NA
B39: Total Working Days | E39: =SUM(E7:E37) -> 13 | F39: to be invoiced
B42: Summary of Days and associated booking numbers*
B44: Number of Days | D44: Netzplan/Auftrag | E44: Vorgang | F44: Element | G44: Project Name
B45: xxx | D45: 9xxxxx | E45: xxxx | F45: xxxx
B46: xxx | D46: 9xxxxx | E46: xxxx | F46: xxxx
B47: xxx | D47: 9xxxxx | E47: xxxx | F47: xxxx
B48: xxx | D48: 9xxxxx | E48: xxxx | F48: xxxx
B49: xxx | D49: 9xxxxx | E49: xxxx | F49: xxxx
B50: xxx | D50: 9xxxxx | E50: xxxx | F50: xxxx
B51: xxx | D51: 9xxxxx | E51: xxxx | F51: xxxx
B53: *it is mandatory to enter the booking numbers - please review with the team leader!
B54: Send the signed work report to your company at the month end.
B55: Invoices from the consultant company will only be accepted with a signed work report.
B57: Date & Signature Contractor
B59: Department / Team Leader Name | F59: Department:_______TL/Name__________________
B60: Date & Signature Team Leader

Sheet Print June Summary
B2: =+'Work Report Consultant'!B2 -> Consultant work report 2026 | G2: ANAVIA AG
B3: =+'Work Report Consultant'!B3 -> Name: | C3: =+'Work Report Consultant'!E3 -> Jorge Benito Sanabrias
B4: =+'Work Report Consultant'!P3 -> 0 | C4: =+'Work Report Consultant'!R3 -> Anzen Engineering Switzerland
B6: =+'Work Report Consultant'!V4 -> JUNE | C6: =+'Work Report Consultant'!AV3 -> 2026 | F6: Comments
B7: =+'Print May Summary'!B37+1 -> 156 | C7: =+'Work Report Consultant'!W5 -> 1 | D7: =+'Work Report Consultant'!X5 -> Holiday | E7: =+'Work Report Consultant'!AF5 -> NA
B8: =+B7+1 -> 157 | C8: =+'Work Report Consultant'!W6 -> 2 | D8: =+'Work Report Consultant'!X6 -> Holiday | E8: =+'Work Report Consultant'!AF6 -> NA
B9: =+B8+1 -> 158 | C9: =+'Work Report Consultant'!W7 -> 3 | D9: =+'Work Report Consultant'!X7 -> Holiday | E9: =+'Work Report Consultant'!AF7 -> NA
B10: =+B9+1 -> 159 | C10: =+'Work Report Consultant'!W8 -> 4 | D10: =+'Work Report Consultant'!X8 -> Holiday | E10: =+'Work Report Consultant'!AF8 -> NA
B11: =+B10+1 -> 160 | C11: =+'Work Report Consultant'!W9 -> 5 | D11: =+'Work Report Consultant'!X9 -> Holiday | E11: =+'Work Report Consultant'!AF9 -> NA
B12: =+B11+1 -> 161 | C12: =+'Work Report Consultant'!W10 -> 6 | D12: =+'Work Report Consultant'!X10 -> N/A | E12: =+'Work Report Consultant'!AF10 -> NA
B13: =+B12+1 -> 162 | C13: =+'Work Report Consultant'!W11 -> 7 | D13: =+'Work Report Consultant'!X11 -> N/A | E13: =+'Work Report Consultant'!AF11 -> NA
B14: =+B13+1 -> 163 | C14: =+'Work Report Consultant'!W12 -> 8 | D14: =+'Work Report Consultant'!X12 -> Holiday | E14: =+'Work Report Consultant'!AF12 -> NA
B15: =+B14+1 -> 164 | C15: =+'Work Report Consultant'!W13 -> 9 | D15: =+'Work Report Consultant'!X13 -> Day | E15: =+'Work Report Consultant'!AF13 -> 1
B16: =+B15+1 -> 165 | C16: =+'Work Report Consultant'!W14 -> 10 | D16: =+'Work Report Consultant'!X14 -> Day | E16: =+'Work Report Consultant'!AF14 -> 1
B17: =+B16+1 -> 166 | C17: =+'Work Report Consultant'!W15 -> 11 | D17: =+'Work Report Consultant'!X15 -> Day | E17: =+'Work Report Consultant'!AF15 -> 1
B18: =+B17+1 -> 167 | C18: =+'Work Report Consultant'!W16 -> 12 | D18: =+'Work Report Consultant'!X16 -> Day | E18: =+'Work Report Consultant'!AF16 -> 1
B19: =+B18+1 -> 168 | C19: =+'Work Report Consultant'!W17 -> 13 | D19: =+'Work Report Consultant'!X17 -> N/A | E19: =+'Work Report Consultant'!AF17 -> NA
... B36: =+B35+1 -> 185 | C36: =+'Work Report Consultant'!W34 -> 30 | D36: =+'Work Report Consultant'!X34 -> Day | E36: =+'Work Report Consultant'!AF34 -> 1
B39: Total Working Days | E39: =SUM(E7:E37) -> 16 | F39: to be invoiced
B42: Summary of Days and associated booking numbers*
B44: Number of Days | D44: Netzplan/Auftrag | E44: Vorgang | F44: Element | G44: Project Name
B45: xxx | D45: 9xxxxx | E45: xxxx | F45: xxxx
B46: xxx | D46: 9xxxxx | E46: xxxx | F46: xxxx
B47: xxx | D47: 9xxxxx | E47: xxxx | F47: xxxx
B48: xxx | D48: 9xxxxx | E48: xxxx | F48: xxxx
B49: xxx | D49: 9xxxxx | E49: xxxx | F49: xxxx
B50: xxx | D50: 9xxxxx | E50: xxxx | F50: xxxx
B51: xxx | D51: 9xxxxx | E51: xxxx | F51: xxxx
B53: *it is mandatory to enter the booking numbers - please review with the team leader!
B54: Send the signed work report to your company at the month end.
B55: Invoices from the consultant company will only be accepted with a signed work report.
B57: Date & Signature Contractor
B59: Department / Team Leader Name | F59: Department:_______TL/Name__________________
B60: Date & Signature Team Leader

Sheet Print July Summary
B2: =+'Work Report Consultant'!B2 -> Consultant work report 2026 | G2: ANAVIA AG
B3: =+'Work Report Consultant'!B3 -> Name: | C3: =+'Work Report Consultant'!E3 -> Jorge Benito Sanabrias
B4: =+'Work Report Consultant'!P3 -> 0 | C4: =+'Work Report Consultant'!R3 -> Anzen Engineering Switzerland
B6: =+'Work Report Consultant'!B40 -> JULY | C6: =+'Work Report Consultant'!AV3 -> 2026 | F6: Comments
B7: =+'Print June Summary'!B36+1 -> 186 | C7: =+'Work Report Consultant'!C41 -> 1 | D7: =+'Work Report Consultant'!D41 -> N/A | E7: =+'Work Report Consultant'!AA41 -> NA
B8: =+B7+1 -> 187 | C8: =+'Work Report Consultant'!C42 -> 2 | D8: =+'Work Report Consultant'!D42 -> N/A | E8: =+'Work Report Consultant'!AA42 -> NA
B9: =+B8+1 -> 188 | C9: =+'Work Report Consultant'!C43 -> 3 | D9: =+'Work Report Consultant'!D43 -> N/A | E9: =+'Work Report Consultant'!AA43 -> NA
B10: =+B9+1 -> 189 | C10: =+'Work Report Consultant'!C44 -> 4 | D10: =+'Work Report Consultant'!D44 -> N/A | E10: =+'Work Report Consultant'!AA44 -> NA
B11: =+B10+1 -> 190 | C11: =+'Work Report Consultant'!C45 -> 5 | D11: =+'Work Report Consultant'!D45 -> N/A | E11: =+'Work Report Consultant'!AA45 -> NA
B12: =+B11+1 -> 191 | C12: =+'Work Report Consultant'!C46 -> 6 | D12: =+'Work Report Consultant'!D46 -> N/A | E12: =+'Work Report Consultant'!AA46 -> NA
B13: =+B12+1 -> 192 | C13: =+'Work Report Consultant'!C47 -> 7 | D13: =+'Work Report Consultant'!D47 -> N/A | E13: =+'Work Report Consultant'!AA47 -> NA
B14: =+B13+1 -> 193 | C14: =+'Work Report Consultant'!C48 -> 8 | D14: =+'Work Report Consultant'!D48 -> N/A | E14: =+'Work Report Consultant'!AA48 -> NA
B15: =+B14+1 -> 194 | C15: =+'Work Report Consultant'!C49 -> 9 | D15: =+'Work Report Consultant'!D49 -> N/A | E15: =+'Work Report Consultant'!AA49 -> NA
B16: =+B15+1 -> 195 | C16: =+'Work Report Consultant'!C50 -> 10 | D16: =+'Work Report Consultant'!D50 -> N/A | E16: =+'Work Report Consultant'!AA50 -> NA
B17: =+B16+1 -> 196 | C17: =+'Work Report Consultant'!C51 -> 11 | D17: =+'Work Report Consultant'!D51 -> N/A | E17: =+'Work Report Consultant'!AA51 -> NA
B18: =+B17+1 -> 197 | C18: =+'Work Report Consultant'!C52 -> 12 | D18: =+'Work Report Consultant'!D52 -> N/A | E18: =+'Work Report Consultant'!AA52 -> NA
B19: =+B18+1 -> 198 | C19: =+'Work Report Consultant'!C53 -> 13 | D19: =+'Work Report Consultant'!D53 -> N/A | E19: =+'Work Report Consultant'!AA53 -> NA
... B37: =+B36+1 -> 216 | C37: =+'Work Report Consultant'!C71 -> 31 | D37: =+'Work Report Consultant'!D71 -> N/A | E37: =+'Work Report Consultant'!AA71 -> NA
B39: Total Working Days | E39: =SUM(E7:E37) -> 0 | F39: to be invoiced
B42: Summary of Days and associated booking numbers*
B44: Number of Days | D44: Netzplan/Auftrag | E44: Vorgang | F44: Element | G44: Project Name
B45: xxx | D45: 9xxxxx | E45: xxxx | F45: xxxx
B46: xxx | D46: 9xxxxx | E46: xxxx | F46: xxxx
B47: xxx | D47: 9xxxxx | E47: xxxx | F47: xxxx
B48: xxx | D48: 9xxxxx | E48: xxxx | F48: xxxx
B49: xxx | D49: 9xxxxx | E49: xxxx | F49: xxxx
B50: xxx | D50: 9xxxxx | E50: xxxx | F50: xxxx
B51: xxx | D51: 9xxxxx | E51: xxxx | F51: xxxx
B53: *it is mandatory to enter the booking numbers - please review with the team leader!
B54: Send the signed work report to your company at the month end.
B55: Invoices from the consultant company will only be accepted with a signed work report.
B57: Date & Signature Contractor
B59: Department / Team Leader Name | F59: Department:_______TL/Name__________________
B60: Date & Signature Team Leader

Sheet Print Aug Summary
B2: =+'Work Report Consultant'!B2 -> Consultant work report 2026 | G2: ANAVIA AG
B3: =+'Work Report Consultant'!B3 -> Name: | C3: =+'Work Report Consultant'!E3 -> Jorge Benito Sanabrias
B4: =+'Work Report Consultant'!P3 -> 0 | C4: =+'Work Report Consultant'!R3 -> Anzen Engineering Switzerland
B6: =+'Work Report Consultant'!F40 -> AUGUST | C6: =+'Work Report Consultant'!AV3 -> 2026 | F6: Comments
B7: =+'Print July Summary'!B37+1 -> 217 | C7: =+'Work Report Consultant'!G41 -> 1 | D7: =+'Work Report Consultant'!H41 -> N/A | E7: =+'Work Report Consultant'!AB41 -> NA
B8: =+B7+1 -> 218 | C8: =+'Work Report Consultant'!G42 -> 2 | D8: =+'Work Report Consultant'!H42 -> N/A | E8: =+'Work Report Consultant'!AB42 -> NA
B9: =+B8+1 -> 219 | C9: =+'Work Report Consultant'!G43 -> 3 | D9: =+'Work Report Consultant'!H43 -> N/A | E9: =+'Work Report Consultant'!AB43 -> NA
B10: =+B9+1 -> 220 | C10: =+'Work Report Consultant'!G44 -> 4 | D10: =+'Work Report Consultant'!H44 -> N/A | E10: =+'Work Report Consultant'!AB44 -> NA
B11: =+B10+1 -> 221 | C11: =+'Work Report Consultant'!G45 -> 5 | D11: =+'Work Report Consultant'!H45 -> N/A | E11: =+'Work Report Consultant'!AB45 -> NA
B12: =+B11+1 -> 222 | C12: =+'Work Report Consultant'!G46 -> 6 | D12: =+'Work Report Consultant'!H46 -> N/A | E12: =+'Work Report Consultant'!AB46 -> NA
B13: =+B12+1 -> 223 | C13: =+'Work Report Consultant'!G47 -> 7 | D13: =+'Work Report Consultant'!H47 -> N/A | E13: =+'Work Report Consultant'!AB47 -> NA
B14: =+B13+1 -> 224 | C14: =+'Work Report Consultant'!G48 -> 8 | D14: =+'Work Report Consultant'!H48 -> N/A | E14: =+'Work Report Consultant'!AB48 -> NA
B15: =+B14+1 -> 225 | C15: =+'Work Report Consultant'!G49 -> 9 | D15: =+'Work Report Consultant'!H49 -> N/A | E15: =+'Work Report Consultant'!AB49 -> NA
B16: =+B15+1 -> 226 | C16: =+'Work Report Consultant'!G50 -> 10 | D16: =+'Work Report Consultant'!H50 -> N/A | E16: =+'Work Report Consultant'!AB50 -> NA
B17: =+B16+1 -> 227 | C17: =+'Work Report Consultant'!G51 -> 11 | D17: =+'Work Report Consultant'!H51 -> N/A | E17: =+'Work Report Consultant'!AB51 -> NA
B18: =+B17+1 -> 228 | C18: =+'Work Report Consultant'!G52 -> 12 | D18: =+'Work Report Consultant'!H52 -> N/A | E18: =+'Work Report Consultant'!AB52 -> NA
